<?xml version="1.0" encoding="utf-8"?>
<robot name="partnet_1a9fa73ca819aa994da5feafe6f1c8fc">
 <link name="base"/>
 <link name="link_0">
  <visual name="drawer_front-46">
   <origin xyz="0 0 0"/>
   <geometry>
    <mesh filename="textured_objs/original-55.obj"/>
   </geometry>
  </visual>
  <visual name="drawer_front-47">
   <origin xyz="0 0 0"/>
   <geometry>
    <mesh filename="textured_objs/original-43.obj"/>
   </geometry>
  </visual>
  <visual name="drawer_side-48">
   <origin xyz="0 0 0"/>
   <geometry>
    <mesh filename="textured_objs/original-42.obj"/>
   </geometry>
  </visual>
  <visual name="drawer_side-49">
   <origin xyz="0 0 0"/>
   <geometry>
    <mesh filename="textured_objs/original-47.obj"/>
   </geometry>
  </visual>
  <visual name="drawer_back-50">
   <origin xyz="0 0 0"/>
   <geometry>
    <mesh filename="textured_objs/original-48.obj"/>
   </geometry>
  </visual>
  <visual name="drawer_bottom-51">
   <origin xyz="0 0 0"/>
   <geometry>
    <mesh filename="textured_objs/original-46.obj"/>
   </geometry>
  </visual>
  <visual name="drawer_bottom-51">
   <origin xyz="0 0 0"/>
   <geometry>
    <mesh filename="textured_objs/original-45.obj"/>
   </geometry>
  </visual>
  <visual name="other_leaf-53">
   <origin xyz="0 0 0"/>
   <geometry>
    <mesh filename="textured_objs/original-49.obj"/>
   </geometry>
  </visual>
  <visual name="handle-45">
   <origin xyz="0 0 0"/>
   <geometry>
    <mesh filename="textured_objs/original-54.obj"/>
   </geometry>
  </visual>
  <visual name="handle-45">
   <origin xyz="0 0 0"/>
   <geometry>
    <mesh filename="textured_objs/original-53.obj"/>
   </geometry>
  </visual>
  <visual name="handle-45">
   <origin xyz="0 0 0"/>
   <geometry>
    <mesh filename="textured_objs/original-52.obj"/>
   </geometry>
  </visual>
  <collision>
   <origin rpy="-5.9604639446321516e-08 -5.960463589360858e-08 5.9604639446321516e-08" xyz="-5.960467319710006e-08 -3.5527141023169746e-15 -3.5527141023169746e-15"/>
   <geometry>
    <mesh filename="cvx_objs/link_0.obj"/>
   </geometry>
  </collision>
 </link>
 <joint name="joint_0" type="prismatic">
  <origin xyz="0 0 0"/>
  <axis xyz="0 0 1"/>
  <child link="link_0"/>
  <parent link="link_4"/>
  <limit lower="0" upper="0.55"/>
 </joint>
 <link name="link_1">
  <visual name="drawer_front-36">
   <origin xyz="0 0 0"/>
   <geometry>
    <mesh filename="textured_objs/original-87.obj"/>
   </geometry>
  </visual>
  <visual name="drawer_front-37">
   <origin xyz="0 0 0"/>
   <geometry>
    <mesh filename="textured_objs/original-75.obj"/>
   </geometry>
  </visual>
  <visual name="drawer_side-38">
   <origin xyz="0 0 0"/>
   <geometry>
    <mesh filename="textured_objs/original-74.obj"/>
   </geometry>
  </visual>
  <visual name="drawer_side-39">
   <origin xyz="0 0 0"/>
   <geometry>
    <mesh filename="textured_objs/original-79.obj"/>
   </geometry>
  </visual>
  <visual name="drawer_back-40">
   <origin xyz="0 0 0"/>
   <geometry>
    <mesh filename="textured_objs/original-80.obj"/>
   </geometry>
  </visual>
  <visual name="drawer_bottom-41">
   <origin xyz="0 0 0"/>
   <geometry>
    <mesh filename="textured_objs/original-78.obj"/>
   </geometry>
  </visual>
  <visual name="drawer_bottom-41">
   <origin xyz="0 0 0"/>
   <geometry>
    <mesh filename="textured_objs/original-77.obj"/>
   </geometry>
  </visual>
  <visual name="other_leaf-43">
   <origin xyz="0 0 0"/>
   <geometry>
    <mesh filename="textured_objs/original-81.obj"/>
   </geometry>
  </visual>
  <visual name="handle-35">
   <origin xyz="0 0 0"/>
   <geometry>
    <mesh filename="textured_objs/original-86.obj"/>
   </geometry>
  </visual>
  <visual name="handle-35">
   <origin xyz="0 0 0"/>
   <geometry>
    <mesh filename="textured_objs/original-84.obj"/>
   </geometry>
  </visual>
  <visual name="handle-35">
   <origin xyz="0 0 0"/>
   <geometry>
    <mesh filename="textured_objs/original-85.obj"/>
   </geometry>
  </visual>
  <collision>
   <origin rpy="-1.788138970226973e-07 5.960461457733879e-08 -1.788138970226973e-07" xyz="1.0658143577500345e-14 5.960470161880949e-08 -1.0658143577500345e-14"/>
   <geometry>
    <mesh filename="cvx_objs/link_1.obj"/>
   </geometry>
  </collision>
 </link>
 <joint name="joint_1" type="prismatic">
  <origin xyz="0 0 0"/>
  <axis xyz="0 0 1"/>
  <child link="link_1"/>
  <parent link="link_4"/>
  <limit lower="0" upper="0.55"/>
 </joint>
 <link name="link_2">
  <visual name="drawer_front-26">
   <origin xyz="0 0 0"/>
   <geometry>
    <mesh filename="textured_objs/original-59.obj"/>
   </geometry>
  </visual>
  <visual name="drawer_front-27">
   <origin xyz="0 0 0"/>
   <geometry>
    <mesh filename="textured_objs/original-71.obj"/>
   </geometry>
  </visual>
  <visual name="drawer_side-28">
   <origin xyz="0 0 0"/>
   <geometry>
    <mesh filename="textured_objs/original-58.obj"/>
   </geometry>
  </visual>
  <visual name="drawer_side-29">
   <origin xyz="0 0 0"/>
   <geometry>
    <mesh filename="textured_objs/original-63.obj"/>
   </geometry>
  </visual>
  <visual name="drawer_back-30">
   <origin xyz="0 0 0"/>
   <geometry>
    <mesh filename="textured_objs/original-64.obj"/>
   </geometry>
  </visual>
  <visual name="drawer_bottom-31">
   <origin xyz="0 0 0"/>
   <geometry>
    <mesh filename="textured_objs/original-62.obj"/>
   </geometry>
  </visual>
  <visual name="drawer_bottom-31">
   <origin xyz="0 0 0"/>
   <geometry>
    <mesh filename="textured_objs/original-61.obj"/>
   </geometry>
  </visual>
  <visual name="other_leaf-33">
   <origin xyz="0 0 0"/>
   <geometry>
    <mesh filename="textured_objs/original-65.obj"/>
   </geometry>
  </visual>
  <visual name="handle-25">
   <origin xyz="0 0 0"/>
   <geometry>
    <mesh filename="textured_objs/original-70.obj"/>
   </geometry>
  </visual>
  <visual name="handle-25">
   <origin xyz="0 0 0"/>
   <geometry>
    <mesh filename="textured_objs/original-68.obj"/>
   </geometry>
  </visual>
  <visual name="handle-25">
   <origin xyz="0 0 0"/>
   <geometry>
    <mesh filename="textured_objs/original-69.obj"/>
   </geometry>
  </visual>
  <collision>
   <origin rpy="-1.4901161238256638e-07 -2.9802320167249267e-08 2.980232460814138e-08" xyz="-5.960464477539063e-08 2.664535047342139e-15 2.9802320611338473e-08"/>
   <geometry>
    <mesh filename="cvx_objs/link_2.obj"/>
   </geometry>
  </collision>
 </link>
 <joint name="joint_2" type="prismatic">
  <origin xyz="0 0 0"/>
  <axis xyz="0 0 1"/>
  <child link="link_2"/>
  <parent link="link_4"/>
  <limit lower="0" upper="0.55"/>
 </joint>
 <link name="link_3">
  <visual name="other_leaf-17">
   <origin xyz="0 0 0"/>
   <geometry>
    <mesh filename="textured_objs/original-33.obj"/>
   </geometry>
  </visual>
  <visual name="drawer_front-18">
   <origin xyz="0 0 0"/>
   <geometry>
    <mesh filename="textured_objs/original-27.obj"/>
   </geometry>
  </visual>
  <visual name="drawer_front-19">
   <origin xyz="0 0 0"/>
   <geometry>
    <mesh filename="textured_objs/original-39.obj"/>
   </geometry>
  </visual>
  <visual name="drawer_side-20">
   <origin xyz="0 0 0"/>
   <geometry>
    <mesh filename="textured_objs/original-31.obj"/>
   </geometry>
  </visual>
  <visual name="drawer_side-21">
   <origin xyz="0 0 0"/>
   <geometry>
    <mesh filename="textured_objs/original-26.obj"/>
   </geometry>
  </visual>
  <visual name="drawer_back-22">
   <origin xyz="0 0 0"/>
   <geometry>
    <mesh filename="textured_objs/original-32.obj"/>
   </geometry>
  </visual>
  <visual name="drawer_bottom-23">
   <origin xyz="0 0 0"/>
   <geometry>
    <mesh filename="textured_objs/original-30.obj"/>
   </geometry>
  </visual>
  <visual name="drawer_bottom-23">
   <origin xyz="0 0 0"/>
   <geometry>
    <mesh filename="textured_objs/original-29.obj"/>
   </geometry>
  </visual>
  <visual name="handle-9">
   <origin xyz="0 0 0"/>
   <geometry>
    <mesh filename="textured_objs/original-38.obj"/>
   </geometry>
  </visual>
  <visual name="handle-9">
   <origin xyz="0 0 0"/>
   <geometry>
    <mesh filename="textured_objs/original-36.obj"/>
   </geometry>
  </visual>
  <visual name="handle-9">
   <origin xyz="0 0 0"/>
   <geometry>
    <mesh filename="textured_objs/original-37.obj"/>
   </geometry>
  </visual>
  <collision>
   <origin rpy="-1.192092611290865e-07 1.1920926112908565e-07 -7.105423969470879e-15" xyz="5.960470161880949e-08 -4.235164736271502e-22 -7.105429051666896e-15"/>
   <geometry>
    <mesh filename="cvx_objs/link_3.obj"/>
   </geometry>
  </collision>
 </link>
 <joint name="joint_3" type="prismatic">
  <origin xyz="0 0 0"/>
  <axis xyz="0 0 1"/>
  <child link="link_3"/>
  <parent link="link_4"/>
  <limit lower="0" upper="0.55"/>
 </joint>
 <link name="link_4">
  <visual name="frame_vertical_bar-75">
   <origin xyz="0 0 0"/>
   <geometry>
    <mesh filename="textured_objs/original-3.obj"/>
   </geometry>
  </visual>
  <visual name="frame_vertical_bar-76">
   <origin xyz="0 0 0"/>
   <geometry>
    <mesh filename="textured_objs/original-7.obj"/>
   </geometry>
  </visual>
  <visual name="frame_horizontal_bar-77">
   <origin xyz="0 0 0"/>
   <geometry>
    <mesh filename="textured_objs/original-21.obj"/>
   </geometry>
  </visual>
  <visual name="frame_horizontal_bar-78">
   <origin xyz="0 0 0"/>
   <geometry>
    <mesh filename="textured_objs/original-20.obj"/>
   </geometry>
  </visual>
  <visual name="frame_horizontal_bar-79">
   <origin xyz="0 0 0"/>
   <geometry>
    <mesh filename="textured_objs/original-6.obj"/>
   </geometry>
  </visual>
  <visual name="frame_horizontal_bar-80">
   <origin xyz="0 0 0"/>
   <geometry>
    <mesh filename="textured_objs/original-22.obj"/>
   </geometry>
  </visual>
  <visual name="frame_horizontal_bar-81">
   <origin xyz="0 0 0"/>
   <geometry>
    <mesh filename="textured_objs/original-17.obj"/>
   </geometry>
  </visual>
  <visual name="vertical_side_panel-82">
   <origin xyz="0 0 0"/>
   <geometry>
    <mesh filename="textured_objs/original-11.obj"/>
   </geometry>
  </visual>
  <visual name="vertical_side_panel-82">
   <origin xyz="0 0 0"/>
   <geometry>
    <mesh filename="textured_objs/original-10.obj"/>
   </geometry>
  </visual>
  <visual name="vertical_side_panel-83">
   <origin xyz="0 0 0"/>
   <geometry>
    <mesh filename="textured_objs/original-15.obj"/>
   </geometry>
  </visual>
  <visual name="vertical_side_panel-83">
   <origin xyz="0 0 0"/>
   <geometry>
    <mesh filename="textured_objs/original-14.obj"/>
   </geometry>
  </visual>
  <visual name="back_panel-84">
   <origin xyz="0 0 0"/>
   <geometry>
    <mesh filename="textured_objs/original-5.obj"/>
   </geometry>
  </visual>
  <visual name="bottom_panel-85">
   <origin xyz="0 0 0"/>
   <geometry>
    <mesh filename="textured_objs/original-2.obj"/>
   </geometry>
  </visual>
  <visual name="bottom_panel-85">
   <origin xyz="0 0 0"/>
   <geometry>
    <mesh filename="textured_objs/original-8.obj"/>
   </geometry>
  </visual>
  <visual name="frame_horizontal_bar-86">
   <origin xyz="0 0 0"/>
   <geometry>
    <mesh filename="textured_objs/original-23.obj"/>
   </geometry>
  </visual>
  <visual name="frame_horizontal_bar-87">
   <origin xyz="0 0 0"/>
   <geometry>
    <mesh filename="textured_objs/original-4.obj"/>
   </geometry>
  </visual>
  <visual name="other_leaf-89">
   <origin xyz="0 0 0"/>
   <geometry>
    <mesh filename="textured_objs/original-88.obj"/>
   </geometry>
  </visual>
  <visual name="base_side_panel-55">
   <origin xyz="0 0 0"/>
   <geometry>
    <mesh filename="textured_objs/original-16.obj"/>
   </geometry>
  </visual>
  <visual name="base_side_panel-56">
   <origin xyz="0 0 0"/>
   <geometry>
    <mesh filename="textured_objs/original-18.obj"/>
   </geometry>
  </visual>
  <visual name="base_side_panel-57">
   <origin xyz="0 0 0"/>
   <geometry>
    <mesh filename="textured_objs/original-12.obj"/>
   </geometry>
  </visual>
  <visual name="base_side_panel-58">
   <origin xyz="0 0 0"/>
   <geometry>
    <mesh filename="textured_objs/original-19.obj"/>
   </geometry>
  </visual>
  <collision>
   <origin rpy="0.0 -0.0 0.0" xyz="-0.0 -0.0 -0.0"/>
   <geometry>
    <mesh filename="cvx_objs/link_4.obj"/>
   </geometry>
  </collision>
 </link>
 <joint name="joint_4" type="fixed">
  <origin rpy="1.570796326794897 0 -1.570796326794897" xyz="0 0 0"/>
  <child link="link_4"/>
  <parent link="base"/>
 </joint>
</robot>